<?xml version="1.0" encoding="UTF-8"?>
<testng-results total="1" passed="0" failed="1" skipped="0">
  <reporter-output>
  </reporter-output>
  <suite started-at="2022-01-24T09:48:03Z" name="Default suite" finished-at="2022-01-24T09:50:20Z" duration-ms="137149">
    <groups>
    </groups>
    <test started-at="2022-01-24T09:48:03Z" name="Default test" finished-at="2022-01-24T09:50:20Z" duration-ms="137149">
      <class name="com.testcases.Testcase">
        <test-method is-config="true" signature="setup()[pri:0, instance:com.testcases.Testcase@2a2da905]" started-at="2022-01-24T15:18:03Z" name="setup" finished-at="2022-01-24T15:19:54Z" duration-ms="111259" status="PASS">
          <reporter-output>
          </reporter-output>
        </test-method> <!-- setup -->
        <test-method signature="validateKidsTopic()[pri:0, instance:com.testcases.Testcase@2a2da905]" started-at="2022-01-24T15:19:54Z" name="validateKidsTopic" finished-at="2022-01-24T15:20:20Z" duration-ms="25838" status="FAIL">
          <exception class="java.lang.AssertionError">
            <message>
              <![CDATA[expected [Shoes] but found [Clothing]]]>
            </message>
            <full-stacktrace>
              <![CDATA[java.lang.AssertionError: expected [Shoes] but found [Clothing]
	at org.testng.Assert.fail(Assert.java:89)
	at org.testng.Assert.failNotEquals(Assert.java:489)
	at org.testng.Assert.assertEquals(Assert.java:118)
	at org.testng.Assert.assertEquals(Assert.java:171)
	at org.testng.Assert.assertEquals(Assert.java:181)
	at com.pages.Homepage.gettextofKidsproducts(Homepage.java:146)
	at com.testcases.Testcase.validateKidsTopic(Testcase.java:112)
	at java.base/jdk.internal.reflect.NativeMethodAccessorImpl.invoke0(Native Method)
	at java.base/jdk.internal.reflect.NativeMethodAccessorImpl.invoke(NativeMethodAccessorImpl.java:77)
	at java.base/jdk.internal.reflect.DelegatingMethodAccessorImpl.invoke(DelegatingMethodAccessorImpl.java:43)
	at java.base/java.lang.reflect.Method.invoke(Method.java:568)
	at org.testng.internal.MethodInvocationHelper.invokeMethod(MethodInvocationHelper.java:80)
	at org.testng.internal.Invoker.invokeMethod(Invoker.java:715)
	at org.testng.internal.Invoker.invokeTestMethod(Invoker.java:907)
	at org.testng.internal.Invoker.invokeTestMethods(Invoker.java:1237)
	at org.testng.internal.TestMethodWorker.invokeTestMethods(TestMethodWorker.java:127)
	at org.testng.internal.TestMethodWorker.run(TestMethodWorker.java:111)
	at org.testng.TestRunner.privateRun(TestRunner.java:767)
	at org.testng.TestRunner.run(TestRunner.java:617)
	at org.testng.SuiteRunner.runTest(SuiteRunner.java:334)
	at org.testng.SuiteRunner.runSequentially(SuiteRunner.java:329)
	at org.testng.SuiteRunner.privateRun(SuiteRunner.java:291)
	at org.testng.SuiteRunner.run(SuiteRunner.java:240)
	at org.testng.SuiteRunnerWorker.runSuite(SuiteRunnerWorker.java:51)
	at org.testng.SuiteRunnerWorker.run(SuiteRunnerWorker.java:85)
	at org.testng.TestNG.runSuitesSequentially(TestNG.java:1197)
	at org.testng.TestNG.runSuitesLocally(TestNG.java:1122)
	at org.testng.TestNG.run(TestNG.java:1030)
	at org.testng.remote.AbstractRemoteTestNG.run(AbstractRemoteTestNG.java:115)
	at org.testng.remote.RemoteTestNG.initAndRun(RemoteTestNG.java:251)
	at org.testng.remote.RemoteTestNG.main(RemoteTestNG.java:77)
]]>
            </full-stacktrace>
          </exception> <!-- java.lang.AssertionError -->
          <reporter-output>
          </reporter-output>
        </test-method> <!-- validateKidsTopic -->
        <test-method is-config="true" signature="closeSetup()[pri:0, instance:com.testcases.Testcase@2a2da905]" started-at="2022-01-24T15:20:20Z" name="closeSetup" finished-at="2022-01-24T15:20:20Z" duration-ms="0" status="PASS">
          <reporter-output>
          </reporter-output>
        </test-method> <!-- closeSetup -->
      </class> <!-- com.testcases.Testcase -->
    </test> <!-- Default test -->
  </suite> <!-- Default suite -->
</testng-results>
